File: ep_1/S2-1800011716.csv
[Measurement conditions]
Sample identification,
Comment - 1,"Configuration=Stage for Flat Samples, Owner=User-1, Creation date=1/29/2018 11:27:37 AM"
Comment - 2,"Goniometer=PW3050/60 (Theta/Theta); Minimum step size 2Theta:0.001; Minimum step size Omega:0.001"
Comment - 3,"Sample stage=PW3071/xx Bracket"
Comment - 4,"Diffractometer system=XPERT-3"
Comment - 5,"Measurement program=C:\PANalytical\Data Collector\Programs\Inorganic Chemistry Experment XRD.xrdmp, Identifier={BED71798-0955-4D0E-A3E8-9E510A9AEFB7}"
Anode material,Cu
K-Alpha1 wavelength,1.5405980
K-Alpha2 wavelength,1.5444260
Ratio K-Alpha2/K-Alpha1,0.500
Divergence slit,Fixed,0.76mm
Monochromator used,NO
Generator voltage, 40
Tube current, 40
File date and time,26/Mar/2021 16:05
Unit cell,
h k l, 0 0 0
Scan axis,Gonio
Scan range,19.500000003,32.501367267
Scan step size,0.0083556
No. of points, 1556
Scan type,CONTINUOUS
Time per step,10.160
[Scan points]
Angle,Intensity
19.504177820,2976.0
19.520889089,2943.0
19.537600358,2944.0
19.554311627,2858.0
19.571022896,2928.0
19.587734165,2900.0
19.604445434,2973.0
19.621156703,2996.0
19.637867972,3019.0
19.654579241,3058.0
19.671290510,3026.0
19.688001779,3055.0
19.704713048,3038.0
19.721424317,3046.0
19.738135586,3095.0
19.754846855,3187.0
19.771558124,3318.0
19.788269393,3302.0
19.804980662,3321.0
19.821691931,3630.0
19.838403200,3819.0
19.855114469,4114.0
19.871825738,4268.0
19.888537006,4747.0
19.905248275,5211.0
19.921959544,5351.0
19.938670813,5508.0
19.955382082,5234.0
19.972093351,5024.0
19.988804620,4881.0
20.005515889,4602.0
20.022227158,4554.0
20.038938427,4594.0
20.055649696,4527.0
20.072360965,4703.0
20.089072234,4520.0
20.105783503,4393.0
20.122494772,4162.0
20.139206041,3881.0
20.155917310,3518.0
20.172628579,3379.0
20.189339848,3171.0
20.206051117,3098.0
20.222762386,3091.0
20.239473655,2907.0
20.256184924,2899.0
20.272896193,2911.0
20.289607462,2922.0
20.306318731,2760.0
20.323030000,2905.0
20.339741269,2915.0
20.356452538,2821.0
20.373163807,2874.0
20.389875076,2873.0
20.406586345,2818.0
20.423297614,3014.0
20.440008883,2896.0
20.456720152,2920.0
20.473431421,2873.0
20.490142690,2973.0
20.506853959,2928.0
20.523565228,2906.0
20.540276497,2826.0
20.556987766,2873.0
20.573699035,2764.0
20.590410304,2727.0
20.607121573,2824.0
20.623832841,2918.0
20.640544110,2753.0
20.657255379,2907.0
20.673966648,2831.0
20.690677917,2861.0
20.707389186,2984.0
20.724100455,3053.0
20.740811724,2975.0
20.757522993,2969.0
20.774234262,2959.0
20.790945531,2882.0
20.807656800,2842.0
20.824368069,2979.0
20.841079338,2952.0
20.857790607,3091.0
20.874501876,2946.0
20.891213145,3086.0
20.907924414,3076.0
20.924635683,3100.0
20.941346952,3098.0
20.958058221,3180.0
20.974769490,3167.0
20.991480759,2982.0
21.008192028,3047.0
21.024903297,2966.0
21.041614566,3062.0
21.058325835,3198.0
21.075037104,3218.0
21.091748373,3143.0
21.108459642,3102.0
21.125170911,3103.0
21.141882180,2978.0
21.158593449,2881.0
21.175304718,2889.0
21.192015987,2817.0
21.208727256,2962.0
21.225438525,3008.0
21.242149794,3018.0
21.258861063,2906.0
21.275572332,2921.0
21.292283601,3011.0
21.308994870,2912.0
21.325706139,2851.0
21.342417408,2899.0
21.359128677,3003.0
21.375839945,2953.0
21.392551214,3070.0
21.409262483,3093.0
21.425973752,3098.0
21.442685021,3126.0
21.459396290,3112.0
21.476107559,3218.0
21.492818828,3197.0
21.509530097,3253.0
21.526241366,3164.0
21.542952635,3094.0
21.559663904,3030.0
21.576375173,2869.0
21.593086442,2823.0
21.609797711,2945.0
21.626508980,2982.0
21.643220249,3026.0
21.659931518,3045.0
21.676642787,2935.0
21.693354056,2915.0
21.710065325,2920.0
21.726776594,2843.0
21.743487863,2977.0
21.760199132,2909.0
21.776910401,2894.0
21.793621670,2956.0
21.810332939,2911.0
21.827044208,3027.0
21.843755477,2951.0
21.860466746,2996.0
21.877178015,2909.0
21.893889284,3060.0
21.910600553,3073.0
21.927311822,3116.0
21.944023091,3120.0
21.960734360,3260.0
21.977445629,3353.0
21.994156898,3363.0
22.010868167,3484.0
22.027579436,3585.0
22.044290705,3672.0
22.061001974,3977.0
22.077713243,4028.0
22.094424512,4131.0
22.111135780,4229.0
22.127847049,4047.0
22.144558318,3924.0
22.161269587,3848.0
22.177980856,3551.0
22.194692125,3458.0
22.211403394,3184.0
22.228114663,3024.0
22.244825932,3082.0
22.261537201,3029.0
22.278248470,3000.0
22.294959739,3005.0
22.311671008,2933.0
22.328382277,2973.0
22.345093546,2909.0
22.361804815,2948.0
22.378516084,3057.0
22.395227353,3000.0
22.411938622,2926.0
22.428649891,2991.0
22.445361160,3057.0
22.462072429,2997.0
22.478783698,3014.0
22.495494967,3081.0
22.512206236,2956.0
22.528917505,3131.0
22.545628774,3094.0
22.562340043,3207.0
22.579051312,3124.0
22.595762581,3182.0
22.612473850,3342.0
22.629185119,3420.0
22.645896388,3517.0
22.662607657,3463.0
22.679318926,3827.0
22.696030195,3730.0
22.712741464,3840.0
22.729452733,3851.0
22.746164002,3772.0
22.762875271,3600.0
22.779586540,3448.0
22.796297809,3309.0
22.813009078,3260.0
22.829720347,3289.0
22.846431615,3119.0
22.863142884,3137.0
22.879854153,3134.0
22.896565422,3072.0
22.913276691,3081.0
22.929987960,3218.0
22.946699229,3249.0
22.963410498,3282.0
22.980121767,3296.0
22.996833036,3422.0
23.013544305,3448.0
23.030255574,3532.0
23.046966843,3552.0
23.063678112,3587.0
23.080389381,3655.0
23.097100650,3393.0
23.113811919,3462.0
23.130523188,3387.0
23.147234457,3305.0
23.163945726,3187.0
23.180656995,3089.0
23.197368264,3081.0
23.214079533,3126.0
23.230790802,2988.0
23.247502071,2984.0
23.264213340,3103.0
23.280924609,3157.0
23.297635878,3029.0
23.314347147,3006.0
23.331058416,3059.0
23.347769685,2997.0
23.364480954,3121.0
23.381192223,3107.0
23.397903492,3154.0
23.414614761,3122.0
23.431326030,3167.0
23.448037299,3132.0
23.464748568,3178.0
23.481459837,3104.0
23.498171106,3130.0
23.514882375,3132.0
23.531593644,3187.0
23.548304913,3240.0
23.565016182,3384.0
23.581727451,3387.0
23.598438719,3372.0
23.615149988,3266.0
23.631861257,3268.0
23.648572526,3105.0
23.665283795,3139.0
23.681995064,3001.0
23.698706333,2881.0
23.715417602,2962.0
23.732128871,3032.0
23.748840140,3043.0
23.765551409,2935.0
23.782262678,2959.0
23.798973947,2897.0
23.815685216,3077.0
23.832396485,3036.0
23.849107754,3159.0
23.865819023,3059.0
23.882530292,3043.0
23.899241561,3173.0
23.915952830,3135.0
23.932664099,3132.0
23.949375368,3108.0
23.966086637,3130.0
23.982797906,3104.0
23.999509175,3258.0
24.016220444,3150.0
24.032931713,3067.0
24.049642982,3131.0
24.066354251,3204.0
24.083065520,3031.0
24.099776789,3155.0
24.116488058,3135.0
24.133199327,3183.0
24.149910596,3587.0
24.166621865,3449.0
24.183333134,3518.0
24.200044403,3530.0
24.216755672,3611.0
24.233466941,3608.0
24.250178210,3518.0
24.266889479,3483.0
24.283600748,3314.0
24.300312017,3318.0
24.317023286,3244.0
24.333734554,3149.0
24.350445823,3109.0
24.367157092,3036.0
24.383868361,3089.0
24.400579630,3077.0
24.417290899,3113.0
24.434002168,3121.0
24.450713437,3091.0
24.467424706,3157.0
24.484135975,3073.0
24.500847244,3088.0
24.517558513,3152.0
24.534269782,3146.0
24.550981051,3060.0
24.567692320,3091.0
24.584403589,3039.0
24.601114858,3093.0
24.617826127,2915.0
24.634537396,3062.0
24.651248665,3087.0
24.667959934,3035.0
24.684671203,2961.0
24.701382472,3098.0
24.718093741,2899.0
24.734805010,3020.0
24.751516279,2916.0
24.768227548,2982.0
24.784938817,2993.0
24.801650086,2884.0
24.818361355,2966.0
24.835072624,2982.0
24.851783893,3020.0
24.868495162,3114.0
24.885206431,3006.0
24.901917700,2965.0
24.918628969,3010.0
24.935340238,3018.0
24.952051507,3001.0
24.968762776,2983.0
24.985474045,2999.0
25.002185314,2999.0
25.018896583,3028.0
25.035607852,3059.0
25.052319121,3047.0
25.069030390,2969.0
25.085741658,2962.0
25.102452927,2999.0
25.119164196,3010.0
25.135875465,3110.0
25.152586734,3064.0
25.169298003,2930.0
25.186009272,3104.0
25.202720541,3145.0
25.219431810,3086.0
25.236143079,3142.0
25.252854348,3247.0
25.269565617,3238.0
25.286276886,3342.0
25.302988155,3509.0
25.319699424,3566.0
25.336410693,3922.0
25.353121962,4225.0
25.369833231,4478.0
25.386544500,4828.0
25.403255769,4940.0
25.419967038,4936.0
25.436678307,4625.0
25.453389576,4325.0
25.470100845,4182.0
25.486812114,3877.0
25.503523383,3561.0
25.520234652,3385.0
25.536945921,3150.0
25.553657190,3135.0
25.570368459,3196.0
25.587079728,3098.0
25.603790997,2956.0
25.620502266,3041.0
25.637213535,2985.0
25.653924804,3056.0
25.670636073,3010.0
25.687347342,3110.0
25.704058611,3008.0
25.720769880,2925.0
25.737481149,2975.0
25.754192418,2974.0
25.770903687,2874.0
25.787614956,3093.0
25.804326225,2986.0
25.821037493,2850.0
25.837748762,3000.0
25.854460031,2973.0
25.871171300,2928.0
25.887882569,3081.0
25.904593838,3041.0
25.921305107,3084.0
25.938016376,3040.0
25.954727645,3024.0
25.971438914,3202.0
25.988150183,3139.0
26.004861452,3251.0
26.021572721,3234.0
26.038283990,3091.0
26.054995259,3105.0
26.071706528,3062.0
26.088417797,3040.0
26.105129066,3081.0
26.121840335,2964.0
26.138551604,3024.0
26.155262873,3105.0
26.171974142,3013.0
26.188685411,3080.0
26.205396680,3024.0
26.222107949,2991.0
26.238819218,3025.0
26.255530487,2912.0
26.272241756,2931.0
26.288953025,2984.0
26.305664294,3060.0
26.322375563,3010.0
26.339086832,3004.0
26.355798101,3076.0
26.372509370,3076.0
26.389220639,3071.0
26.405931908,3056.0
26.422643177,3056.0
26.439354446,3042.0
26.456065715,3022.0
26.472776984,3093.0
26.489488253,3125.0
26.506199522,3118.0
26.522910791,3229.0
26.539622060,3130.0
26.556333329,3334.0
26.573044597,3177.0
26.589755866,3204.0
26.606467135,3201.0
26.623178404,3214.0
26.639889673,3165.0
26.656600942,3166.0
26.673312211,3074.0
26.690023480,3154.0
26.706734749,3051.0
26.723446018,3167.0
26.740157287,3055.0
26.756868556,3007.0
26.773579825,2984.0
26.790291094,3001.0
26.807002363,2840.0
26.823713632,3095.0
26.840424901,3041.0
26.857136170,3077.0
26.873847439,2944.0
26.890558708,2922.0
26.907269977,2993.0
26.923981246,3086.0
26.940692515,3040.0
26.957403784,2998.0
26.974115053,3066.0
26.990826322,3068.0
27.007537591,2964.0
27.024248860,3043.0
27.040960129,3114.0
27.057671398,2983.0
27.074382667,3066.0
27.091093936,2985.0
27.107805205,3125.0
27.124516474,2917.0
27.141227743,3066.0
27.157939012,2973.0
27.174650281,3005.0
27.191361550,3070.0
27.208072819,3097.0
27.224784088,3019.0
27.241495357,2972.0
27.258206626,2997.0
27.274917895,2986.0
27.291629164,3039.0
27.308340432,3000.0
27.325051701,3099.0
27.341762970,3072.0
27.358474239,3188.0
27.375185508,3068.0
27.391896777,3104.0
27.408608046,3154.0
27.425319315,3062.0
27.442030584,3172.0
27.458741853,3135.0
27.475453122,3053.0
27.492164391,3003.0
27.508875660,3014.0
27.525586929,2976.0
27.542298198,3092.0
27.559009467,3224.0
27.575720736,3072.0
27.592432005,3137.0
27.609143274,3239.0
27.625854543,3264.0
27.642565812,3187.0
27.659277081,3214.0
27.675988350,3342.0
27.692699619,3297.0
27.709410888,3423.0
27.726122157,3698.0
27.742833426,3788.0
27.759544695,4063.0
27.776255964,4179.0
27.792967233,4436.0
27.809678502,4642.0
27.826389771,4367.0
27.843101040,4032.0
27.859812309,3882.0
27.876523578,3948.0
27.893234847,3550.0
27.909946116,3605.0
27.926657385,3584.0
27.943368654,3447.0
27.960079923,3472.0
27.976791192,3562.0
27.993502461,3412.0
28.010213730,3576.0
28.026924999,3597.0
28.043636267,3682.0
28.060347536,3717.0
28.077058805,3679.0
28.093770074,3739.0
28.110481343,3616.0
28.127192612,3644.0
28.143903881,3581.0
28.160615150,3844.0
28.177326419,3841.0
28.194037688,3965.0
28.210748957,4349.0
28.227460226,4486.0
28.244171495,5046.0
28.260882764,5134.0
28.277594033,5584.0
28.294305302,5812.0
28.311016571,6498.0
28.327727840,7313.0
28.344439109,8112.0
28.361150378,8718.0
28.377861647,8979.0
28.394572916,8521.0
28.411284185,7977.0
28.427995454,7241.0
28.444706723,6648.0
28.461417992,5927.0
28.478129261,5293.0
28.494840530,4672.0
28.511551799,4162.0
28.528263068,3812.0
28.544974337,3542.0
28.561685606,3504.0
28.578396875,3456.0
28.595108144,3382.0
28.611819413,3407.0
28.628530682,3359.0
28.645241951,3246.0
28.661953220,3232.0
28.678664489,3272.0
28.695375758,3110.0
28.712087027,3322.0
28.728798296,3243.0
28.745509565,3332.0
28.762220834,3344.0
28.778932103,3323.0
28.795643371,3382.0
28.812354640,3241.0
28.829065909,3343.0
28.845777178,3289.0
28.862488447,3297.0
28.879199716,3161.0
28.895910985,3276.0
28.912622254,3268.0
28.929333523,3285.0
28.946044792,3293.0
28.962756061,3149.0
28.979467330,3282.0
28.996178599,3314.0
29.012889868,3324.0
29.029601137,3532.0
29.046312406,3515.0
29.063023675,3543.0
29.079734944,3508.0
29.096446213,3827.0
29.113157482,3979.0
29.129868751,4168.0
29.146580020,4528.0
29.163291289,4917.0
29.180002558,5416.0
29.196713827,5985.0
29.213425096,6750.0
29.230136365,7477.0
29.246847634,8104.0
29.263558903,8651.0
29.280270172,8456.0
29.296981441,8056.0
29.313692710,7134.0
29.330403979,6377.0
29.347115248,5858.0
29.363826517,5302.0
29.380537786,4696.0
29.397249055,4073.0
29.413960324,3736.0
29.430671593,3567.0
29.447382862,3373.0
29.464094131,3354.0
29.480805400,3374.0
29.497516669,3438.0
29.514227938,3352.0
29.530939206,3303.0
29.547650475,3307.0
29.564361744,3411.0
29.581073013,3224.0
29.597784282,3244.0
29.614495551,3256.0
29.631206820,3416.0
29.647918089,3411.0
29.664629358,3364.0
29.681340627,3437.0
29.698051896,3498.0
29.714763165,3606.0
29.731474434,3697.0
29.748185703,3813.0
29.764896972,3877.0
29.781608241,4053.0
29.798319510,4550.0
29.815030779,4936.0
29.831742048,5486.0
29.848453317,6000.0
29.865164586,6698.0
29.881875855,7273.0
29.898587124,7682.0
29.915298393,7695.0
29.932009662,7122.0
29.948720931,6590.0
29.965432200,6053.0
29.982143469,5643.0
29.998854738,5081.0
30.015566007,4539.0
30.032277276,4244.0
30.048988545,3720.0
30.065699814,3668.0
30.082411083,3656.0
30.099122352,3525.0
30.115833621,3530.0
30.132544890,3713.0
30.149256159,3683.0
30.165967428,3943.0
30.182678697,3841.0
30.199389966,3868.0
30.216101235,3804.0
30.232812504,3603.0
30.249523773,3667.0
30.266235042,3528.0
30.282946310,3358.0
30.299657579,3355.0
30.316368848,3149.0
30.333080117,3122.0
30.349791386,3165.0
30.366502655,3143.0
30.383213924,3133.0
30.399925193,3217.0
30.416636462,3160.0
30.433347731,3164.0
30.450059000,3152.0
30.466770269,3194.0
30.483481538,3166.0
30.500192807,3208.0
30.516904076,3140.0
30.533615345,3232.0
30.550326614,3140.0
30.567037883,3212.0
30.583749152,3142.0
30.600460421,3230.0
30.617171690,3119.0
30.633882959,3208.0
30.650594228,3164.0
30.667305497,3036.0
30.684016766,3144.0
30.700728035,3119.0
30.717439304,3086.0
30.734150573,3031.0
30.750861842,3142.0
30.767573111,3126.0
30.784284380,3225.0
30.800995649,3224.0
30.817706918,3177.0
30.834418187,3198.0
30.851129456,3248.0
30.867840725,3120.0
30.884551994,3285.0
30.901263263,3184.0
30.917974532,3220.0
30.934685801,3340.0
30.951397070,3195.0
30.968108339,3260.0
30.984819608,3455.0
31.001530877,3395.0
31.018242145,3321.0
31.034953414,3503.0
31.051664683,3438.0
31.068375952,3496.0
31.085087221,3543.0
31.101798490,3661.0
31.118509759,3533.0
31.135221028,3832.0
31.151932297,4066.0
31.168643566,4061.0
31.185354835,3948.0
31.202066104,3720.0
31.218777373,3795.0
31.235488642,3766.0
31.252199911,3735.0
31.268911180,3725.0
31.285622449,3803.0
31.302333718,3924.0
31.319044987,3936.0
31.335756256,4214.0
31.352467525,4453.0
31.369178794,5068.0
31.385890063,5282.0
31.402601332,5072.0
31.419312601,4829.0
31.436023870,4424.0
31.452735139,4267.0
31.469446408,4298.0
31.486157677,3781.0
31.502868946,3644.0
31.519580215,3443.0
31.536291484,3301.0
31.553002753,3133.0
31.569714022,3225.0
31.586425291,3180.0
31.603136560,3182.0
31.619847829,3124.0
31.636559098,3134.0
31.653270367,3053.0
31.669981636,3230.0
31.686692905,3098.0
31.703404174,3028.0
31.720115443,3111.0
31.736826712,3189.0
31.753537981,3199.0
31.770249249,3222.0
31.786960518,3122.0
31.803671787,3143.0
31.820383056,3145.0
31.837094325,3080.0
31.853805594,3040.0
31.870516863,3020.0
31.887228132,3191.0
31.903939401,3195.0
31.920650670,3266.0
31.937361939,3228.0
31.954073208,3215.0
31.970784477,3264.0
31.987495746,3459.0
32.004207015,3615.0
32.020918284,3700.0
32.037629553,3937.0
32.054340822,4025.0
32.071052091,4313.0
32.087763360,4496.0
32.104474629,4625.0
32.121185898,4499.0
32.137897167,4579.0
32.154608436,4162.0
32.171319705,4053.0
32.188030974,3954.0
32.204742243,3769.0
32.221453512,3661.0
32.238164781,3538.0
32.254876050,3404.0
32.271587319,3333.0
32.288298588,3261.0
32.305009857,3288.0
32.321721126,3285.0
32.338432395,3321.0
32.355143664,3437.0
32.371854933,3399.0
32.388566202,3524.0
32.405277471,3569.0
32.421988740,3629.0
32.438700009,3864.0
32.455411278,3660.0
32.472122547,3793.0
32.488833816,3877.0
32.497189450,3865.0